Watching for file changes with StatReloader
Not Found: /
[30/Sep/2023 08:28:49] "GET / HTTP/1.1" 404 2672
Not Found: /favicon.ico
[30/Sep/2023 08:28:50] "GET /favicon.ico HTTP/1.1" 404 2723
Not Found: /paln
[30/Sep/2023 08:28:54] "GET /paln HTTP/1.1" 404 2702
Not Found: /
[30/Sep/2023 09:02:59] "GET / HTTP/1.1" 404 2672
Not Found: /plan/location/
[30/Sep/2023 09:03:09] "GET /plan/location/ HTTP/1.1" 404 3938
[30/Sep/2023 09:03:17] "GET /plan/create HTTP/1.1" 301 0
[30/Sep/2023 09:03:17] "GET /plan/create/ HTTP/1.1" 302 0
Not Found: /accounts/login/
[30/Sep/2023 09:03:17] "GET /accounts/login/?next=/plan/create/ HTTP/1.1" 404 2754
Not Found: /plan/plan_create
[30/Sep/2023 09:03:35] "GET /plan/plan_create HTTP/1.1" 404 3944
Not Found: /plan/1/plan_create
[30/Sep/2023 09:03:42] "GET /plan/1/plan_create HTTP/1.1" 404 3950
/Users/joe/Desktop/wemeet_app/meet/config/settings/base.py changed, reloading.
Performing system checks...

System check identified no issues (0 silenced).

You have 3 unapplied migration(s). Your project may not work properly until you apply the migrations for app(s): account, plan.
Run 'python manage.py migrate' to apply them.
September 30, 2023 - 08:28:37
Django version 4.2.5, using settings 'config.settings.test'
Starting development server at http://0.0.0.0:8000/
Quit the server with CONTROL-C.

Watching for file changes with StatReloader
Exception in thread django-main-thread:
Traceback (most recent call last):
  File "/Users/joe/miniconda3/lib/python3.10/threading.py", line 1016, in _bootstrap_inner
    self.run()
  File "/Users/joe/miniconda3/lib/python3.10/threading.py", line 953, in run
    self._target(*self._args, **self._kwargs)
  File "/Users/joe/Desktop/wemeet_app/venv/lib/python3.10/site-packages/django/utils/autoreload.py", line 64, in wrapper
    fn(*args, **kwargs)
  File "/Users/joe/Desktop/wemeet_app/venv/lib/python3.10/site-packages/django/core/management/commands/runserver.py", line 125, in inner_run
    autoreload.raise_last_exception()
  File "/Users/joe/Desktop/wemeet_app/venv/lib/python3.10/site-packages/django/utils/autoreload.py", line 87, in raise_last_exception
    raise _exception[1]
  File "/Users/joe/Desktop/wemeet_app/venv/lib/python3.10/site-packages/django/core/management/__init__.py", line 394, in execute
    autoreload.check_errors(django.setup)()
  File "/Users/joe/Desktop/wemeet_app/venv/lib/python3.10/site-packages/django/utils/autoreload.py", line 64, in wrapper
    fn(*args, **kwargs)
  File "/Users/joe/Desktop/wemeet_app/venv/lib/python3.10/site-packages/django/__init__.py", line 24, in setup
    apps.populate(settings.INSTALLED_APPS)
  File "/Users/joe/Desktop/wemeet_app/venv/lib/python3.10/site-packages/django/apps/registry.py", line 93, in populate
    raise ImproperlyConfigured(
django.core.exceptions.ImproperlyConfigured: Application labels aren't unique, duplicates: auth
/Users/joe/Desktop/wemeet_app/meet/config/settings/base.py changed, reloading.
Watching for file changes with StatReloader
/Users/joe/Desktop/wemeet_app/meet/config/settings/base.py changed, reloading.
Performing system checks...

System check identified no issues (0 silenced).
September 30, 2023 - 09:31:36
Django version 4.2.5, using settings 'config.settings.test'
Starting development server at http://0.0.0.0:8000/
Quit the server with CONTROL-C.

Watching for file changes with StatReloader
Exception in thread django-main-thread:
Traceback (most recent call last):
  File "/Users/joe/miniconda3/lib/python3.10/threading.py", line 1016, in _bootstrap_inner
    self.run()
  File "/Users/joe/miniconda3/lib/python3.10/threading.py", line 953, in run
    self._target(*self._args, **self._kwargs)
  File "/Users/joe/Desktop/wemeet_app/venv/lib/python3.10/site-packages/django/utils/autoreload.py", line 64, in wrapper
    fn(*args, **kwargs)
  File "/Users/joe/Desktop/wemeet_app/venv/lib/python3.10/site-packages/django/core/management/commands/runserver.py", line 125, in inner_run
    autoreload.raise_last_exception()
  File "/Users/joe/Desktop/wemeet_app/venv/lib/python3.10/site-packages/django/utils/autoreload.py", line 87, in raise_last_exception
    raise _exception[1]
  File "/Users/joe/Desktop/wemeet_app/venv/lib/python3.10/site-packages/django/core/management/__init__.py", line 394, in execute
    autoreload.check_errors(django.setup)()
  File "/Users/joe/Desktop/wemeet_app/venv/lib/python3.10/site-packages/django/utils/autoreload.py", line 64, in wrapper
    fn(*args, **kwargs)
  File "/Users/joe/Desktop/wemeet_app/venv/lib/python3.10/site-packages/django/__init__.py", line 24, in setup
    apps.populate(settings.INSTALLED_APPS)
  File "/Users/joe/Desktop/wemeet_app/venv/lib/python3.10/site-packages/django/apps/registry.py", line 91, in populate
    app_config = AppConfig.create(entry)
  File "/Users/joe/Desktop/wemeet_app/venv/lib/python3.10/site-packages/django/apps/config.py", line 193, in create
    import_module(entry)
  File "/Users/joe/miniconda3/lib/python3.10/importlib/__init__.py", line 126, in import_module
    return _bootstrap._gcd_import(name[level:], package, level)
  File "<frozen importlib._bootstrap>", line 1050, in _gcd_import
  File "<frozen importlib._bootstrap>", line 1027, in _find_and_load
  File "<frozen importlib._bootstrap>", line 1004, in _find_and_load_unlocked
ModuleNotFoundError: No module named 'meet'
/Users/joe/Desktop/wemeet_app/meet/config/settings/base.py changed, reloading.
Watching for file changes with StatReloader
/Users/joe/Desktop/wemeet_app/meet/config/settings/base.py changed, reloading.
Performing system checks...

System check identified no issues (0 silenced).
September 30, 2023 - 09:31:55
Django version 4.2.5, using settings 'config.settings.test'
Starting development server at http://0.0.0.0:8000/
Quit the server with CONTROL-C.

Watching for file changes with StatReloader
Exception in thread django-main-thread:
Traceback (most recent call last):
  File "/Users/joe/miniconda3/lib/python3.10/threading.py", line 1016, in _bootstrap_inner
    self.run()
  File "/Users/joe/miniconda3/lib/python3.10/threading.py", line 953, in run
    self._target(*self._args, **self._kwargs)
  File "/Users/joe/Desktop/wemeet_app/venv/lib/python3.10/site-packages/django/utils/autoreload.py", line 64, in wrapper
    fn(*args, **kwargs)
  File "/Users/joe/Desktop/wemeet_app/venv/lib/python3.10/site-packages/django/core/management/commands/runserver.py", line 125, in inner_run
    autoreload.raise_last_exception()
  File "/Users/joe/Desktop/wemeet_app/venv/lib/python3.10/site-packages/django/utils/autoreload.py", line 87, in raise_last_exception
    raise _exception[1]
  File "/Users/joe/Desktop/wemeet_app/venv/lib/python3.10/site-packages/django/core/management/__init__.py", line 394, in execute
    autoreload.check_errors(django.setup)()
  File "/Users/joe/Desktop/wemeet_app/venv/lib/python3.10/site-packages/django/utils/autoreload.py", line 64, in wrapper
    fn(*args, **kwargs)
  File "/Users/joe/Desktop/wemeet_app/venv/lib/python3.10/site-packages/django/__init__.py", line 24, in setup
    apps.populate(settings.INSTALLED_APPS)
  File "/Users/joe/Desktop/wemeet_app/venv/lib/python3.10/site-packages/django/apps/registry.py", line 93, in populate
    raise ImproperlyConfigured(
django.core.exceptions.ImproperlyConfigured: Application labels aren't unique, duplicates: auth
/Users/joe/Desktop/wemeet_app/meet/config/settings/base.py changed, reloading.
Watching for file changes with StatReloader
/Users/joe/Desktop/wemeet_app/meet/plan/models.py changed, reloading.
Performing system checks...

System check identified no issues (0 silenced).
September 30, 2023 - 09:40:17
Django version 4.2.5, using settings 'config.settings.test'
Starting development server at http://0.0.0.0:8000/
Quit the server with CONTROL-C.

Watching for file changes with StatReloader
Exception in thread django-main-thread:
Traceback (most recent call last):
  File "/Users/joe/miniconda3/lib/python3.10/threading.py", line 1016, in _bootstrap_inner
    self.run()
  File "/Users/joe/miniconda3/lib/python3.10/threading.py", line 953, in run
    self._target(*self._args, **self._kwargs)
  File "/Users/joe/Desktop/wemeet_app/venv/lib/python3.10/site-packages/django/utils/autoreload.py", line 64, in wrapper
    fn(*args, **kwargs)
  File "/Users/joe/Desktop/wemeet_app/venv/lib/python3.10/site-packages/django/core/management/commands/runserver.py", line 133, in inner_run
    self.check(display_num_errors=True)
  File "/Users/joe/Desktop/wemeet_app/venv/lib/python3.10/site-packages/django/core/management/base.py", line 556, in check
    raise SystemCheckError(msg)
django.core.management.base.SystemCheckError: SystemCheckError: System check identified some issues:

ERRORS:
plan.Group.plan: (fields.E300) Field defines a relation with model 'Plan', which is either not installed, or is abstract.

System check identified 1 issue (0 silenced).
/Users/joe/Desktop/wemeet_app/meet/plan/models.py changed, reloading.
Performing system checks...

Watching for file changes with StatReloader
/Users/joe/Desktop/wemeet_app/meet/auth/urls.py changed, reloading.
Performing system checks...

System check identified no issues (0 silenced).
September 30, 2023 - 09:43:40
Django version 4.2.5, using settings 'config.settings.test'
Starting development server at http://0.0.0.0:8000/
Quit the server with CONTROL-C.

Watching for file changes with StatReloader
/Users/joe/Desktop/wemeet_app/meet/config/settings/base.py changed, reloading.
Performing system checks...

System check identified no issues (0 silenced).
September 30, 2023 - 09:44:55
Django version 4.2.5, using settings 'config.settings.test'
Starting development server at http://0.0.0.0:8000/
Quit the server with CONTROL-C.

Watching for file changes with StatReloader
Exception in thread django-main-thread:
Traceback (most recent call last):
  File "/Users/joe/miniconda3/lib/python3.10/threading.py", line 1016, in _bootstrap_inner
    self.run()
  File "/Users/joe/miniconda3/lib/python3.10/threading.py", line 953, in run
    self._target(*self._args, **self._kwargs)
  File "/Users/joe/Desktop/wemeet_app/venv/lib/python3.10/site-packages/django/utils/autoreload.py", line 64, in wrapper
    fn(*args, **kwargs)
  File "/Users/joe/Desktop/wemeet_app/venv/lib/python3.10/site-packages/django/core/management/commands/runserver.py", line 125, in inner_run
    autoreload.raise_last_exception()
  File "/Users/joe/Desktop/wemeet_app/venv/lib/python3.10/site-packages/django/utils/autoreload.py", line 87, in raise_last_exception
    raise _exception[1]
  File "/Users/joe/Desktop/wemeet_app/venv/lib/python3.10/site-packages/django/core/management/__init__.py", line 394, in execute
    autoreload.check_errors(django.setup)()
  File "/Users/joe/Desktop/wemeet_app/venv/lib/python3.10/site-packages/django/utils/autoreload.py", line 64, in wrapper
    fn(*args, **kwargs)
  File "/Users/joe/Desktop/wemeet_app/venv/lib/python3.10/site-packages/django/__init__.py", line 24, in setup
    apps.populate(settings.INSTALLED_APPS)
  File "/Users/joe/Desktop/wemeet_app/venv/lib/python3.10/site-packages/django/apps/registry.py", line 91, in populate
    app_config = AppConfig.create(entry)
  File "/Users/joe/Desktop/wemeet_app/venv/lib/python3.10/site-packages/django/apps/config.py", line 193, in create
    import_module(entry)
  File "/Users/joe/miniconda3/lib/python3.10/importlib/__init__.py", line 126, in import_module
    return _bootstrap._gcd_import(name[level:], package, level)
  File "<frozen importlib._bootstrap>", line 1050, in _gcd_import
  File "<frozen importlib._bootstrap>", line 1027, in _find_and_load
  File "<frozen importlib._bootstrap>", line 992, in _find_and_load_unlocked
  File "<frozen importlib._bootstrap>", line 241, in _call_with_frames_removed
  File "<frozen importlib._bootstrap>", line 1050, in _gcd_import
  File "<frozen importlib._bootstrap>", line 1027, in _find_and_load
  File "<frozen importlib._bootstrap>", line 1004, in _find_and_load_unlocked
ModuleNotFoundError: No module named 'meet'
/Users/joe/Desktop/wemeet_app/meet/config/settings/base.py changed, reloading.
Watching for file changes with StatReloader
/Users/joe/Desktop/wemeet_app/meet/config/settings/base.py changed, reloading.
Performing system checks...

System check identified no issues (0 silenced).
September 30, 2023 - 09:47:01
Django version 4.2.5, using settings 'config.settings.test'
Starting development server at http://0.0.0.0:8000/
Quit the server with CONTROL-C.

Watching for file changes with StatReloader
Exception in thread django-main-thread:
Traceback (most recent call last):
  File "/Users/joe/Desktop/wemeet_app/venv/lib/python3.10/site-packages/django/apps/config.py", line 210, in create
    app_module = import_module(app_name)
  File "/Users/joe/miniconda3/lib/python3.10/importlib/__init__.py", line 126, in import_module
    return _bootstrap._gcd_import(name[level:], package, level)
  File "<frozen importlib._bootstrap>", line 1050, in _gcd_import
  File "<frozen importlib._bootstrap>", line 1027, in _find_and_load
  File "<frozen importlib._bootstrap>", line 1004, in _find_and_load_unlocked
ModuleNotFoundError: No module named 'auth'

During handling of the above exception, another exception occurred:

Traceback (most recent call last):
  File "/Users/joe/miniconda3/lib/python3.10/threading.py", line 1016, in _bootstrap_inner
    self.run()
  File "/Users/joe/miniconda3/lib/python3.10/threading.py", line 953, in run
    self._target(*self._args, **self._kwargs)
  File "/Users/joe/Desktop/wemeet_app/venv/lib/python3.10/site-packages/django/utils/autoreload.py", line 64, in wrapper
    fn(*args, **kwargs)
  File "/Users/joe/Desktop/wemeet_app/venv/lib/python3.10/site-packages/django/core/management/commands/runserver.py", line 125, in inner_run
    autoreload.raise_last_exception()
  File "/Users/joe/Desktop/wemeet_app/venv/lib/python3.10/site-packages/django/utils/autoreload.py", line 87, in raise_last_exception
    raise _exception[1]
  File "/Users/joe/Desktop/wemeet_app/venv/lib/python3.10/site-packages/django/core/management/__init__.py", line 394, in execute
    autoreload.check_errors(django.setup)()
  File "/Users/joe/Desktop/wemeet_app/venv/lib/python3.10/site-packages/django/utils/autoreload.py", line 64, in wrapper
    fn(*args, **kwargs)
  File "/Users/joe/Desktop/wemeet_app/venv/lib/python3.10/site-packages/django/__init__.py", line 24, in setup
    apps.populate(settings.INSTALLED_APPS)
  File "/Users/joe/Desktop/wemeet_app/venv/lib/python3.10/site-packages/django/apps/registry.py", line 91, in populate
    app_config = AppConfig.create(entry)
  File "/Users/joe/Desktop/wemeet_app/venv/lib/python3.10/site-packages/django/apps/config.py", line 212, in create
    raise ImproperlyConfigured(
django.core.exceptions.ImproperlyConfigured: Cannot import 'auth'. Check that 'authenticate.apps.AuthConfig.name' is correct.
/Users/joe/Desktop/wemeet_app/meet/config/settings/base.py changed, reloading.
Watching for file changes with StatReloader
/Users/joe/Desktop/wemeet_app/meet/plan/views.py changed, reloading.
Performing system checks...

System check identified no issues (0 silenced).
September 30, 2023 - 09:52:22
Django version 4.2.5, using settings 'config.settings.test'
Starting development server at http://0.0.0.0:8000/
Quit the server with CONTROL-C.

Watching for file changes with StatReloader
/Users/joe/Desktop/wemeet_app/meet/plan/views.py changed, reloading.
Performing system checks...

System check identified no issues (0 silenced).
September 30, 2023 - 10:12:52
Django version 4.2.5, using settings 'config.settings.test'
Starting development server at http://0.0.0.0:8000/
Quit the server with CONTROL-C.

Watching for file changes with StatReloader
/Users/joe/Desktop/wemeet_app/meet/plan/views.py changed, reloading.
Performing system checks...

System check identified no issues (0 silenced).
September 30, 2023 - 10:13:26
Django version 4.2.5, using settings 'config.settings.test'
Starting development server at http://0.0.0.0:8000/
Quit the server with CONTROL-C.

Watching for file changes with StatReloader
/Users/joe/Desktop/wemeet_app/meet/plan/views.py changed, reloading.
Performing system checks...

System check identified no issues (0 silenced).
September 30, 2023 - 10:13:40
Django version 4.2.5, using settings 'config.settings.test'
Starting development server at http://0.0.0.0:8000/
Quit the server with CONTROL-C.

Watching for file changes with StatReloader
Not Found: /plan/1/plan_create
[30/Sep/2023 11:52:20] "GET /plan/1/plan_create HTTP/1.1" 404 3950
/Users/joe/Desktop/wemeet_app/meet/plan/views.py changed, reloading.
Performing system checks...

System check identified no issues (0 silenced).
September 30, 2023 - 10:30:07
Django version 4.2.5, using settings 'config.settings.test'
Starting development server at http://0.0.0.0:8000/
Quit the server with CONTROL-C.

Watching for file changes with StatReloader
/Users/joe/Desktop/wemeet_app/meet/plan/views.py changed, reloading.
Performing system checks...

System check identified no issues (0 silenced).
September 30, 2023 - 12:25:37
Django version 4.2.5, using settings 'config.settings.test'
Starting development server at http://0.0.0.0:8000/
Quit the server with CONTROL-C.

Watching for file changes with StatReloader
Not Found: /
[30/Sep/2023 13:41:45] "GET / HTTP/1.1" 404 2672
Not Found: /plan/location/
[30/Sep/2023 13:41:49] "GET /plan/location/ HTTP/1.1" 404 3938
Not Found: /plan/location/12/delete
[30/Sep/2023 13:42:00] "GET /plan/location/12/delete HTTP/1.1" 404 3965
/Users/joe/Desktop/wemeet_app/meet/plan/views.py changed, reloading.
Performing system checks...

System check identified no issues (0 silenced).
September 30, 2023 - 13:37:30
Django version 4.2.5, using settings 'config.settings.test'
Starting development server at http://0.0.0.0:8000/
Quit the server with CONTROL-C.

Watching for file changes with StatReloader
Not Found: /
[30/Sep/2023 13:58:47] "GET / HTTP/1.1" 404 2672
[30/Sep/2023 13:58:49] "GET /admin/ HTTP/1.1" 302 0
[30/Sep/2023 13:58:49] "GET /admin/login/?next=/admin/ HTTP/1.1" 200 4181
[30/Sep/2023 13:58:50] "GET /static/admin/css/dark_mode.css HTTP/1.1" 200 2929
[30/Sep/2023 13:58:50] "GET /static/admin/css/responsive.css HTTP/1.1" 200 18533
[30/Sep/2023 13:58:50] "GET /static/admin/js/theme.js HTTP/1.1" 200 1943
[30/Sep/2023 13:58:50] "GET /static/admin/css/nav_sidebar.css HTTP/1.1" 200 2694
[30/Sep/2023 13:58:50] "GET /static/admin/css/base.css HTTP/1.1" 200 21207
[30/Sep/2023 13:58:50] "GET /static/admin/css/login.css HTTP/1.1" 200 958
[30/Sep/2023 13:58:50] "GET /static/admin/js/nav_sidebar.js HTTP/1.1" 200 3063
Not Found: /post
[30/Sep/2023 13:58:57] "GET /post HTTP/1.1" 404 2702
Not Found: /plan/location/
[30/Sep/2023 13:59:02] "GET /plan/location/ HTTP/1.1" 404 3938
[30/Sep/2023 13:59:11] "GET /plan/create/ HTTP/1.1" 302 0
Not Found: /accounts/login/
[30/Sep/2023 13:59:11] "GET /accounts/login/?next=/plan/create/ HTTP/1.1" 404 2754
[30/Sep/2023 13:59:21] "GET /admin/ HTTP/1.1" 302 0
[30/Sep/2023 13:59:21] "GET /admin/login/?next=/admin/ HTTP/1.1" 200 4181
[30/Sep/2023 13:59:23] "POST /admin/login/?next=/admin/ HTTP/1.1" 302 0
[30/Sep/2023 13:59:23] "GET /admin/ HTTP/1.1" 200 7453
[30/Sep/2023 13:59:23] "GET /static/admin/css/dashboard.css HTTP/1.1" 200 441
[30/Sep/2023 13:59:23] "GET /static/admin/img/icon-addlink.svg HTTP/1.1" 200 331
[30/Sep/2023 13:59:23] "GET /static/admin/img/icon-changelink.svg HTTP/1.1" 200 380
[30/Sep/2023 13:59:31] "GET /plan/create/ HTTP/1.1" 200 2163
[30/Sep/2023 13:59:53] "GET /plan/ HTTP/1.1" 200 1969
[30/Sep/2023 13:59:59] "GET /plan/create/ HTTP/1.1" 200 2163
[30/Sep/2023 14:00:03] "GET /plan/ HTTP/1.1" 200 1969
/Users/joe/Desktop/wemeet_app/meet/account/viewsets.py changed, reloading.
Performing system checks...

System check identified no issues (0 silenced).
September 30, 2023 - 13:52:29
Django version 4.2.5, using settings 'config.settings.test'
Starting development server at http://0.0.0.0:8000/
Quit the server with CONTROL-C.

Watching for file changes with StatReloader
/Users/joe/Desktop/wemeet_app/meet/auth/viewsets/refresh.py changed, reloading.
Performing system checks...

System check identified no issues (0 silenced).
September 30, 2023 - 14:01:59
Django version 4.2.5, using settings 'config.settings.test'
Starting development server at http://0.0.0.0:8000/
Quit the server with CONTROL-C.

Watching for file changes with StatReloader
/Users/joe/Desktop/wemeet_app/meet/plan/views.py changed, reloading.
Performing system checks...

System check identified no issues (0 silenced).
September 30, 2023 - 14:02:02
Django version 4.2.5, using settings 'config.settings.test'
Starting development server at http://0.0.0.0:8000/
Quit the server with CONTROL-C.

Watching for file changes with StatReloader
/Users/joe/Desktop/wemeet_app/meet/config/settings/base.py changed, reloading.
Performing system checks...

System check identified no issues (0 silenced).
September 30, 2023 - 14:03:50
Django version 4.2.5, using settings 'config.settings.test'
Starting development server at http://0.0.0.0:8000/
Quit the server with CONTROL-C.

Watching for file changes with StatReloader
Exception in thread django-main-thread:
Traceback (most recent call last):
  File "/Users/joe/miniconda3/lib/python3.10/threading.py", line 1016, in _bootstrap_inner
    self.run()
  File "/Users/joe/miniconda3/lib/python3.10/threading.py", line 953, in run
    self._target(*self._args, **self._kwargs)
  File "/Users/joe/Desktop/wemeet_app/venv/lib/python3.10/site-packages/django/utils/autoreload.py", line 64, in wrapper
    fn(*args, **kwargs)
  File "/Users/joe/Desktop/wemeet_app/venv/lib/python3.10/site-packages/django/core/management/commands/runserver.py", line 125, in inner_run
    autoreload.raise_last_exception()
  File "/Users/joe/Desktop/wemeet_app/venv/lib/python3.10/site-packages/django/utils/autoreload.py", line 87, in raise_last_exception
    raise _exception[1]
  File "/Users/joe/Desktop/wemeet_app/venv/lib/python3.10/site-packages/django/core/management/__init__.py", line 394, in execute
    autoreload.check_errors(django.setup)()
  File "/Users/joe/Desktop/wemeet_app/venv/lib/python3.10/site-packages/django/utils/autoreload.py", line 64, in wrapper
    fn(*args, **kwargs)
  File "/Users/joe/Desktop/wemeet_app/venv/lib/python3.10/site-packages/django/__init__.py", line 24, in setup
    apps.populate(settings.INSTALLED_APPS)
  File "/Users/joe/Desktop/wemeet_app/venv/lib/python3.10/site-packages/django/apps/registry.py", line 91, in populate
    app_config = AppConfig.create(entry)
  File "/Users/joe/Desktop/wemeet_app/venv/lib/python3.10/site-packages/django/apps/config.py", line 193, in create
    import_module(entry)
  File "/Users/joe/miniconda3/lib/python3.10/importlib/__init__.py", line 126, in import_module
    return _bootstrap._gcd_import(name[level:], package, level)
  File "<frozen importlib._bootstrap>", line 1050, in _gcd_import
  File "<frozen importlib._bootstrap>", line 1027, in _find_and_load
  File "<frozen importlib._bootstrap>", line 992, in _find_and_load_unlocked
  File "<frozen importlib._bootstrap>", line 241, in _call_with_frames_removed
  File "<frozen importlib._bootstrap>", line 1050, in _gcd_import
  File "<frozen importlib._bootstrap>", line 1027, in _find_and_load
  File "<frozen importlib._bootstrap>", line 1004, in _find_and_load_unlocked
ModuleNotFoundError: No module named 'app'
/Users/joe/Desktop/wemeet_app/meet/config/settings/base.py changed, reloading.
Watching for file changes with StatReloader
Error: That port is already in use.
Watching for file changes with StatReloader
Not Found: /
[04/Oct/2023 01:13:47] "GET / HTTP/1.1" 404 2672
Not Found: /
[04/Oct/2023 01:13:48] "GET / HTTP/1.1" 404 2672
[04/Oct/2023 01:13:57] "GET /plan/ HTTP/1.1" 200 1969
Not Found: /plan/template
[04/Oct/2023 01:15:03] "GET /plan/template HTTP/1.1" 404 3935
Not Found: /plan/templates
[04/Oct/2023 01:15:06] "GET /plan/templates HTTP/1.1" 404 3938
/Users/joe/Desktop/wemeet_app/meet/plan/forms.py changed, reloading.
Performing system checks...

System check identified no issues (0 silenced).
October 04, 2023 - 01:13:46
Django version 4.2.5, using settings 'config.settings.test'
Starting development server at http://0.0.0.0:8000/
Quit the server with CONTROL-C.

Watching for file changes with StatReloader
/Users/joe/Desktop/wemeet_app/meet/config/urls.py changed, reloading.
Performing system checks...

System check identified no issues (0 silenced).
October 04, 2023 - 01:23:43
Django version 4.2.5, using settings 'config.settings.test'
Starting development server at http://0.0.0.0:8000/
Quit the server with CONTROL-C.

Watching for file changes with StatReloader
Exception in thread django-main-thread:
Traceback (most recent call last):
  File "/Users/joe/miniconda3/lib/python3.10/threading.py", line 1016, in _bootstrap_inner
    self.run()
  File "/Users/joe/miniconda3/lib/python3.10/threading.py", line 953, in run
    self._target(*self._args, **self._kwargs)
  File "/Users/joe/Desktop/wemeet_app/venv/lib/python3.10/site-packages/django/utils/autoreload.py", line 64, in wrapper
    fn(*args, **kwargs)
  File "/Users/joe/Desktop/wemeet_app/venv/lib/python3.10/site-packages/django/core/management/commands/runserver.py", line 125, in inner_run
    autoreload.raise_last_exception()
  File "/Users/joe/Desktop/wemeet_app/venv/lib/python3.10/site-packages/django/utils/autoreload.py", line 87, in raise_last_exception
    raise _exception[1]
  File "/Users/joe/Desktop/wemeet_app/venv/lib/python3.10/site-packages/django/core/management/__init__.py", line 394, in execute
    autoreload.check_errors(django.setup)()
  File "/Users/joe/Desktop/wemeet_app/venv/lib/python3.10/site-packages/django/utils/autoreload.py", line 64, in wrapper
    fn(*args, **kwargs)
  File "/Users/joe/Desktop/wemeet_app/venv/lib/python3.10/site-packages/django/__init__.py", line 24, in setup
    apps.populate(settings.INSTALLED_APPS)
  File "/Users/joe/Desktop/wemeet_app/venv/lib/python3.10/site-packages/django/apps/registry.py", line 91, in populate
    app_config = AppConfig.create(entry)
  File "/Users/joe/Desktop/wemeet_app/venv/lib/python3.10/site-packages/django/apps/config.py", line 193, in create
    import_module(entry)
  File "/Users/joe/miniconda3/lib/python3.10/importlib/__init__.py", line 126, in import_module
    return _bootstrap._gcd_import(name[level:], package, level)
  File "<frozen importlib._bootstrap>", line 1050, in _gcd_import
  File "<frozen importlib._bootstrap>", line 1027, in _find_and_load
  File "<frozen importlib._bootstrap>", line 1004, in _find_and_load_unlocked
ModuleNotFoundError: No module named 'bootstrap4'
